Traceback (most recent call last):
  File "/usr/local/lib/python3.9/dist-packages/jupyter_cache/executors/utils.py", line 58, in single_nb_execution
    executenb(
  File "/usr/local/lib/python3.9/dist-packages/nbclient/client.py", line 1204, in execute
    return NotebookClient(nb=nb, resources=resources, km=km, **kwargs).execute()
  File "/usr/local/lib/python3.9/dist-packages/nbclient/util.py", line 84, in wrapped
    return just_run(coro(*args, **kwargs))
  File "/usr/local/lib/python3.9/dist-packages/nbclient/util.py", line 62, in just_run
    return loop.run_until_complete(coro)
  File "/usr/lib/python3.9/asyncio/base_events.py", line 647, in run_until_complete
    return future.result()
  File "/usr/local/lib/python3.9/dist-packages/nbclient/client.py", line 663, in async_execute
    await self.async_execute_cell(
  File "/usr/local/lib/python3.9/dist-packages/nbclient/client.py", line 965, in async_execute_cell
    await self._check_raise_for_error(cell, cell_index, exec_reply)
  File "/usr/local/lib/python3.9/dist-packages/nbclient/client.py", line 862, in _check_raise_for_error
    raise CellExecutionError.from_cell_and_msg(cell, exec_reply_content)
nbclient.exceptions.CellExecutionError: An error occurred while executing the following cell:
------------------
# membaca dataset csv dari url
url = 'https://raw.githubusercontent.com/kb22/Heart-Disease-Prediction/master/dataset.csv'
data = pd.read_csv(url)
------------------

[0;31m[0m
[0;31mNameError[0mTraceback (most recent call last)
[0;32m<ipython-input-1-d32f3bd0c579>[0m in [0;36m<cell line: 3>[0;34m()[0m
[1;32m      1[0m [0;31m# membaca dataset csv dari url[0m[0;34m[0m[0;34m[0m[0m
[1;32m      2[0m [0murl[0m [0;34m=[0m [0;34m'https://raw.githubusercontent.com/kb22/Heart-Disease-Prediction/master/dataset.csv'[0m[0;34m[0m[0;34m[0m[0m
[0;32m----> 3[0;31m [0mdata[0m [0;34m=[0m [0mpd[0m[0;34m.[0m[0mread_csv[0m[0;34m([0m[0murl[0m[0;34m)[0m[0;34m[0m[0;34m[0m[0m
[0m
[0;31mNameError[0m: name 'pd' is not defined
NameError: name 'pd' is not defined

